Workbook
Name DadosExternos_1: Orçado!$A$1
Name ListaClientes: [1]!Clientes[Cliente]
Name ListaCT: [1]!CTs[CT]
Name ListaÍndice: [1]!Índices[Índice]
Name ListaProduto: [1]!Produtos[Produto]
Name ListaProdutoClasse: [1]!Produtos[CLASSE]
Name ListaProdutos: [1]!Produtos[#Data]
Name ListaServiço: [1]!Serviços[Serviço]

Sheet Lista de Produtos CLASSIFICAÇÃO
A1: Produtos | B1: Grupo | C1: Densidade M³ | I1: Grupo dados | L1: Aquecidos | M1: Biocombustíveis | N1: Derivados | O1: Metanol | P1: Óleo Vegetal | Q1: Outros
A2: ÁCIDO GRAXO | B2: Outros | C2: 0.9 | I2: Aquecidos | L2: BIODIESEL DE SEBO | M2: ALCOOL ETILICO ANIDRO | N2: AROMATICO PESADO | O2: ALCOOL METILICO | P2: BYPASS | Q2: ALIMET
A3: ACOSTAGEM | B3: Acostagem | C3: 0 | I3: Biocombustíveis | L3: ESTEARINA DE PALMA RBD | M3: ALCOOL ETILICO HIDRATADO | N3: DERIVADOS | O3: METANOL | P3: OLEO DE ALGODAO | Q3: DESAFIO
A4: ACOSTAGEM | B4: Outros | C4: 0.92 | I4: Derivados | L4: ESTEARINA DE PALMISTE | M4: BIODIESEL | N4: DERIVADOS DE PETRÓLEO | O4: METHANOL | P4: OLEO DE GIRASSOL | Q4: DIETILENO GLICOL
A5: ÁGUARRAS MINERAL | B5: Outros | C5: 0.79 | I5: Metanol | L5: MELAÇO DE CANA | M5: ETANOL | N5: DIESEL | P5: ÓLEO DE GIRASSOL | Q5: DIETILENO GLICOL (DEG)
A6: ALCOOL ETILICO ANIDRO | B6: Biocombustíveis | C6: 0.8 | I6: Óleo Vegetal | L6: OLEINA DE PALMA | N6: DIESEL S10 | P6: OLEO DE MILHO | Q6: FERTILIZANTE LIQUIDO
A7: ALCOOL ETILICO HIDRATADO | B7: Biocombustíveis | C7: 0.8 | I7: Acostagem | L7: OLEO DE PALMA | N7: DIESEL S500 | P7: OLEO DE MILHO BRUTO DEGOM | Q7: FERTILIZANTE LIQUIDO (UAN
A8: ALCOOL METILICO | B8: Metanol | C8: 0.79 | I8: Soda Caustica | L8: ÓLEO DE PALMA | N8: FERRO | P8: OLEO DE SOJA BRUTO | Q8: GLICERINA
A9: ALIMET | B9: Outros | C9: 1.3 | I9: Outros | L9: OLEO DE PALMA BRUTO | N9: GASOLINA | P9: OLEO DE SOJA BRUTO DEGOMA | Q9: LISINA
A10: AROMATICO PESADO | B10: Derivados | C10: 0.7 | L10: OLEO DE PALMISTE | N10: MTBE | P10: OLEO DE SOJA REFINADO | Q10: METILATO DE SÓDIO
A11: BIODIESEL | B11: Biocombustíveis | C11: 0.86 | L11: ÓLEO DE PALMISTE | N11: NAFTA | P11: OLEO DE CANOLA | Q11: METILATO DE SODIO 30%
A12: BIODIESEL DE SEBO | B12: Aquecidos | C12: 0.9 | L12: OLEO DE PALMISTE BRUTO | N12: NAFTA BAIXA OCTANAGEM | P12: ÓLEO DE SOJA REFINADO | Q12: METILTIO
A13: BYPASS | B13: Óleo Vegetal | C13: 0.92 | H13: Acostagem | I13: Óleo de Soja | L13: OLEOS AQUECIDOS | N13: OLEO DIESEL S10 | Q13: METILTIO BUTANOICO ACIDO
A14: DERIVADOS | B14: Derivados | C14: 0.83 | H14: Álcool | I14: Óleo Veg. | J14: ÓLEO VEGETAL | L14: PALMA | N14: OLEO DIESEL S500 | Q14: OLEFINAS
A15: DERIVADOS DE PETRÓLEO | B15: Derivados | C15: 0.83 | H15: Aquecidos | I15: Soda Caustica | J15: SODA CÁUSTICA | L15: PALMA BRUTA | N15: REFORMADO PESADO | Q15: OUTROS
A16: DESAFIO | B16: Outros | C16: 1 | H16: Biodiesel | I16: Biodiesel | J16: BIODIESEL | L16: PALMA REFINADA | N16: XILENO MISTO | Q16: RHODIMET GRANEL
A17: DIESEL | B17: Derivados | C17: 0.83 | H17: Derivados | I17: Álcool | J17: ÁLCOOL | L17: PALMA/PALMISTE | Q17: SODA CAUSTICA
A18: DIESEL S10 | B18: Derivados | C18: 0.83 | H18: Metanol | I18: Aquecidos | J18: AQUECIDOS | L18: PALMA/PALMISTE/ESTEARINA | Q18: SODA CAUSTICA DIAFRAGMA
A19: DIESEL S500 | B19: Derivados | C19: 0.83 | H19: Óleo de Soja | I19: Metanol | J19: METANOL | K19: ALIMET | L19: PALMISTE | Q19: SODA CAUSTICA LIQMEMBRANA
A20: DIETILENO GLICOL | B20: Outros | C20: 1.2 | H20: Óleo Veg. | I20: Derivados | J20: DIESEL/GASOLINA | L20: SEBO BOVINO | Q20: TEREBINTINA
A21: DIETILENO GLICOL (DEG) | B21: Outros | C21: 1.2 | H21: Outros | I21: Outros | J21: METILATO | Q21: XILENO MISTO
A22: ESTEARINA DE PALMA RBD | B22: Aquecidos | C22: 0.9 | H22: Soda Caustica | Q22: ACOSTAGEM
A23: ESTEARINA DE PALMISTE | B23: Aquecidos | C23: 0.9
A24: ESTEARINA PALMA/PALMISTE | B24: Aquecidos | C24: 0.9
A25: ETANOL | B25: Biocombustíveis | C25: 0.8
A26: FENOL | B26: Outros | C26: 1.07
A27: FERRO | B27: Derivados | C27: 0.83
A28: FERTILIZANTE LIQUIDO | B28: Outros | C28: 1.3
A29: FERTILIZANTE LIQUIDO (UAN | B29: Outros | C29: 1.3
A30: G A V | B30: Derivados | C30: 0.72
A31: ÁLCOOL ETIL. DESNAT. | B31: Biocombustíveis | C31: 0.8
A32: GASOLINA | B32: Derivados | C32: 0.79
A33: GLICERINA | B33: Outros | C33: 1.2
A34: GORDURA ANIMAL | B34: Aquecidos | C34: 0.9
... A94: XILENO MISTO | B94: Outros | C94: 0.8654
A103: ÓLEO DE SOJA | B103: Óleo Vegetal
A104: ÓLEO DE ALGODÃO | B104: Óleo Vegetal
A105: ÓLEO DE GIRASSOL | B105: Óleo Vegetal
A106: ÓLEO DE MILHO | B106: Óleo Vegetal
A107: ÓLEO DE CANOLA | B107: Óleo Vegetal
...

Sheet Banco de Dados - Fat.
A1: ANO | B1: MÊS | C1: Cliente | D1: PRODUTO | E1: GRUPO DE PRODUTOS | F1: Faturamento (R$) | G1: Grupo de Cliente
A2: 2021 | B2: Janeiro | C2: Adisseo | D2: ALIMET | E2: =VLOOKUP(D2,'Lista de Produtos CLASSIFICAÇÃO'!$A$103:$B$144,2,FALSE) -> Outros | F2: 515772 | G2: =VLOOKUP(C2,clientes!$C$3:$D$60,2,FALSE) -> ADISSEO
A3: 2021 | B3: Janeiro | C3: Adisseo | D3: ALIMET | E3: =VLOOKUP(D3,'Lista de Produtos CLASSIFICAÇÃO'!$A$103:$B$144,2,FALSE) -> Outros | F3: 0 | G3: =VLOOKUP(C3,clientes!$C$3:$D$60,2,FALSE) -> ADISSEO
A4: 2021 | B4: Janeiro | C4: Adisseo Caminhão | D4: ALIMET | E4: =VLOOKUP(D4,'Lista de Produtos CLASSIFICAÇÃO'!$A$103:$B$144,2,FALSE) -> Outros | F4: 3316 | G4: =VLOOKUP(C4,clientes!$C$3:$D$60,2,FALSE) -> ADISSEO
A5: 2021 | B5: Janeiro | C5: ADM | D5: GLICERINA | E5: =VLOOKUP(D5,'Lista de Produtos CLASSIFICAÇÃO'!$A$103:$B$144,2,FALSE) -> Outros | F5: 76113 | G5: =VLOOKUP(C5,clientes!$C$3:$D$60,2,FALSE) -> ADM
A6: 2021 | B6: Janeiro | C6: Ipiranga | D6: DIESEL/GASOLINA | E6: =VLOOKUP(D6,'Lista de Produtos CLASSIFICAÇÃO'!$A$103:$B$144,2,FALSE) -> Derivados | F6: 6963862 | G6: =VLOOKUP(C6,clientes!$C$3:$D$60,2,FALSE) -> IPIRANGA
A7: 2021 | B7: Janeiro | C7: BR | D7: DIESEL/GASOLINA | E7: =VLOOKUP(D7,'Lista de Produtos CLASSIFICAÇÃO'!$A$103:$B$144,2,FALSE) -> Derivados | F7: 4188725 | G7: =VLOOKUP(C7,clientes!$C$3:$D$60,2,FALSE) -> BR
A8: 2021 | B8: Janeiro | C8: Greenergy | D8: DIESEL/GASOLINA | E8: =VLOOKUP(D8,'Lista de Produtos CLASSIFICAÇÃO'!$A$103:$B$144,2,FALSE) -> Derivados | F8: 1765906 | G8: =VLOOKUP(C8,clientes!$C$3:$D$60,2,FALSE) -> GREENENERGY
A9: 2021 | B9: Janeiro | C9: Sul Plata | D9: DIESEL/GASOLINA | E9: =VLOOKUP(D9,'Lista de Produtos CLASSIFICAÇÃO'!$A$103:$B$144,2,FALSE) -> Derivados | F9: 3478569 | G9: =VLOOKUP(C9,clientes!$C$3:$D$60,2,FALSE) -> SUL PLATA
A10: 2021 | B10: Janeiro | C10: Sul Plata | D10: DIESEL/GASOLINA | E10: =VLOOKUP(D10,'Lista de Produtos CLASSIFICAÇÃO'!$A$103:$B$144,2,FALSE) -> Derivados | F10: 0 | G10: =VLOOKUP(C10,clientes!$C$3:$D$60,2,FALSE) -> SUL PLATA
A11: 2021 | B11: Janeiro | C11: JBS | D11: SODA CÁUSTICA | E11: =VLOOKUP(D11,'Lista de Produtos CLASSIFICAÇÃO'!$A$103:$B$144,2,FALSE) -> Soda Caustica | F11: 129223 | G11: =VLOOKUP(C11,clientes!$C$3:$D$60,2,FALSE) -> JBS
A12: 2021 | B12: Janeiro | C12: Tricon | D12: SODA CÁUSTICA | E12: =VLOOKUP(D12,'Lista de Produtos CLASSIFICAÇÃO'!$A$103:$B$144,2,FALSE) -> Soda Caustica | F12: 305822 | G12: =VLOOKUP(C12,clientes!$C$3:$D$60,2,FALSE) -> TRICON ENERGY
A13: 2021 | B13: Janeiro | C13: Novus | D13: ALIMET | E13: =VLOOKUP(D13,'Lista de Produtos CLASSIFICAÇÃO'!$A$103:$B$144,2,FALSE) -> Outros | F13: 203290 | G13: =VLOOKUP(C13,clientes!$C$3:$D$60,2,FALSE) -> NOVUS
... A1762: 2025 | B1762: Março | C1762: Ciapetro | D1762: DIESEL/GASOLINA | E1762: =VLOOKUP(D1762,'Lista de Produtos CLASSIFICAÇÃO'!$A$103:$B$144,2,FALSE) -> Derivados | F1762: 1076739 | G1762: =VLOOKUP(C1762,clientes!$C$3:$D$60,2,FALSE) -> CIAPETRO
A1763: 2025 | B1763: Março | C1763: Tereos/Inpasa/Glencore/FS | D1763: ÁLCOOL | E1763: =VLOOKUP(D1763,'Lista de Produtos CLASSIFICAÇÃO'!$A$103:$B$144,2,FALSE) -> Biocombustíveis | F1763: 900000 | G1763: =VLOOKUP(C1763,clientes!$C$3:$D$60,2,FALSE) -> TEREOS / INPASA / GLENCORE / FS | I1763: 1.6319983e+08
A1764: 2025 | B1764: Março | C1764: Ares | D1764: AQUECIDOS | E1764: =VLOOKUP(D1764,'Lista de Produtos CLASSIFICAÇÃO'!$A$103:$B$144,2,FALSE) -> Aquecidos | F1764: 608544 | G1764: =VLOOKUP(C1764,clientes!$C$3:$D$60,2,FALSE) -> ARES MERCHANTS PTE LIMITE
A1765: 2025 | B1765: Março | C1765: Acostagem | D1765: ACOSTAGEM | E1765: =VLOOKUP(D1765,'Lista de Produtos CLASSIFICAÇÃO'!$A$103:$B$144,2,FALSE) -> Acostagem | F1765: 537930.51 | G1765: =VLOOKUP(C1765,clientes!$C$3:$D$60,2,FALSE) -> ACOSTAGEM
A1766: 2025 | B1766: Março | C1766: ICOF | D1766: AQUECIDOS | E1766: =VLOOKUP(D1766,'Lista de Produtos CLASSIFICAÇÃO'!$A$103:$B$144,2,FALSE) -> Aquecidos | F1766: 557826 | G1766: =VLOOKUP(C1766,clientes!$C$3:$D$60,2,FALSE) -> ICOF
A1767: 2025 | B1767: Março | C1767: GPC | D1767: SODA CÁUSTICA | E1767: =VLOOKUP(D1767,'Lista de Produtos CLASSIFICAÇÃO'!$A$103:$B$144,2,FALSE) -> Soda Caustica | F1767: 158585 | G1767: =VLOOKUP(C1767,clientes!$C$3:$D$60,2,FALSE) -> GPC
A1768: 2025 | B1768: Março | C1768: Inpasa | D1768: ÁLCOOL | E1768: =VLOOKUP(D1768,'Lista de Produtos CLASSIFICAÇÃO'!$A$103:$B$144,2,FALSE) -> Biocombustíveis | F1768: 1477279 | G1768: =VLOOKUP(C1768,clientes!$C$3:$D$60,2,FALSE) -> INPASA
A1769: 2025 | B1769: Abril | C1769: Adisseo | D1769: ALIMET | E1769: =VLOOKUP(D1769,'Lista de Produtos CLASSIFICAÇÃO'!$A$103:$B$144,2,FALSE) -> Outros | F1769: 878484 | G1769: =VLOOKUP(C1769,clientes!$C$3:$D$60,2,FALSE) -> ADISSEO
A1770: 2025 | B1770: Abril | C1770: Bunge | D1770: AQUECIDOS | E1770: =VLOOKUP(D1770,'Lista de Produtos CLASSIFICAÇÃO'!$A$103:$B$144,2,FALSE) -> Aquecidos | F1770: 378593 | G1770: =VLOOKUP(C1770,clientes!$C$3:$D$60,2,FALSE) -> BUNGE
A1771: 2025 | B1771: Abril | C1771: ADM | D1771: ÓLEO VEGETAL | E1771: =VLOOKUP(D1771,'Lista de Produtos CLASSIFICAÇÃO'!$A$103:$B$144,2,FALSE) -> Óleo Vegetal | F1771: 161866 | G1771: =VLOOKUP(C1771,clientes!$C$3:$D$60,2,FALSE) -> ADM
A1772: 2025 | B1772: Abril | C1772: Ipiranga | D1772: DIESEL/GASOLINA | E1772: =VLOOKUP(D1772,'Lista de Produtos CLASSIFICAÇÃO'!$A$103:$B$144,2,FALSE) -> Derivados | F1772: 5957914 | G1772: =VLOOKUP(C1772,clientes!$C$3:$D$60,2,FALSE) -> IPIRANGA
A1773: 2025 | B1773: Abril | C1773: Raizen | D1773: DIESEL/GASOLINA | E1773: =VLOOKUP(D1773,'Lista de Produtos CLASSIFICAÇÃO'!$A$103:$B$144,2,FALSE) -> Derivados | F1773: 3979329 | G1773: =VLOOKUP(C1773,clientes!$C$3:$D$60,2,FALSE) -> RAIZEN
A1774: 2025 | B1774: Abril | C1774: Vibra | D1774: DIESEL/GASOLINA | E1774: =VLOOKUP(D1774,'Lista de Produtos CLASSIFICAÇÃO'!$A$103:$B$144,2,FALSE) -> Derivados | F1774: 1971343 | G1774: =VLOOKUP(C1774,clientes!$C$3:$D$60,2,FALSE) -> VIBRA
A1775: 2025 | B1775: Abril | C1775: Sul Plata | D1775: DIESEL/GASOLINA | E1775: =VLOOKUP(D1775,'Lista de Produtos CLASSIFICAÇÃO'!$A$103:$B$144,2,FALSE) -> Derivados | F1775: 3059732 | G1775: =VLOOKUP(C1775,clientes!$C$3:$D$60,2,FALSE) -> SUL PLATA
... A2181: 2026 | B2181: Dezembro | C2181: Sul Plata | D2181: DIESEL/GASOLINA | E2181: =VLOOKUP(D2181,'Lista de Produtos CLASSIFICAÇÃO'!$A$103:$B$144,2,FALSE) -> Derivados | F2181: 2911532 | G2181: =VLOOKUP(C2181,clientes!$C$3:$D$60,2,FALSE) -> SUL PLATA
A2182: 2026 | B2182: Janeiro | C2182: JBS | D2182: SODA CÁUSTICA | E2182: Soda Cáustica | F2182: 217045 | G2182: =VLOOKUP(C2182,clientes!$C$3:$D$60,2,FALSE) -> JBS
A2183: 2026 | B2183: Fevereiro | C2183: JBS | D2183: SODA CÁUSTICA | E2183: Soda Cáustica | F2183: 217045 | G2183: =VLOOKUP(C2183,clientes!$C$3:$D$60,2,FALSE) -> JBS
A2184: 2026 | B2184: Março | C2184: JBS | D2184: SODA CÁUSTICA | E2184: Soda Cáustica | F2184: 217045 | G2184: =VLOOKUP(C2184,clientes!$C$3:$D$60,2,FALSE) -> JBS
A2185: 2026 | B2185: Abril | C2185: JBS | D2185: SODA CÁUSTICA | E2185: =VLOOKUP(D2185,'Lista de Produtos CLASSIFICAÇÃO'!$A$103:$B$144,2,FALSE) -> Soda Caustica | F2185: 217045 | G2185: =VLOOKUP(C2185,clientes!$C$3:$D$60,2,FALSE) -> JBS
A2186: 2026 | B2186: Maio | C2186: JBS | D2186: SODA CÁUSTICA | E2186: =VLOOKUP(D2186,'Lista de Produtos CLASSIFICAÇÃO'!$A$103:$B$144,2,FALSE) -> Soda Caustica | F2186: 217045 | G2186: =VLOOKUP(C2186,clientes!$C$3:$D$60,2,FALSE) -> JBS
A2187: 2026 | B2187: Junho | C2187: JBS | D2187: SODA CÁUSTICA | E2187: =VLOOKUP(D2187,'Lista de Produtos CLASSIFICAÇÃO'!$A$103:$B$144,2,FALSE) -> Soda Caustica | F2187: 217045 | G2187: =VLOOKUP(C2187,clientes!$C$3:$D$60,2,FALSE) -> JBS
A2188: 2026 | B2188: Julho | C2188: JBS | D2188: SODA CÁUSTICA | E2188: =VLOOKUP(D2188,'Lista de Produtos CLASSIFICAÇÃO'!$A$103:$B$144,2,FALSE) -> Soda Caustica | F2188: 217045 | G2188: =VLOOKUP(C2188,clientes!$C$3:$D$60,2,FALSE) -> JBS
A2189: 2026 | B2189: Agosto | C2189: JBS | D2189: SODA CÁUSTICA | E2189: =VLOOKUP(D2189,'Lista de Produtos CLASSIFICAÇÃO'!$A$103:$B$144,2,FALSE) -> Soda Caustica | F2189: 217045 | G2189: =VLOOKUP(C2189,clientes!$C$3:$D$60,2,FALSE) -> JBS
A2190: 2026 | B2190: Setembro | C2190: JBS | D2190: SODA CÁUSTICA | E2190: =VLOOKUP(D2190,'Lista de Produtos CLASSIFICAÇÃO'!$A$103:$B$144,2,FALSE) -> Soda Caustica | F2190: 217045 | G2190: =VLOOKUP(C2190,clientes!$C$3:$D$60,2,FALSE) -> JBS
A2191: 2026 | B2191: Outubro | C2191: JBS | D2191: SODA CÁUSTICA | E2191: =VLOOKUP(D2191,'Lista de Produtos CLASSIFICAÇÃO'!$A$103:$B$144,2,FALSE) -> Soda Caustica | F2191: 226921 | G2191: =VLOOKUP(C2191,clientes!$C$3:$D$60,2,FALSE) -> JBS
A2192: 2026 | B2192: Novembro | C2192: JBS | D2192: SODA CÁUSTICA | E2192: =VLOOKUP(D2192,'Lista de Produtos CLASSIFICAÇÃO'!$A$103:$B$144,2,FALSE) -> Soda Caustica | F2192: 226921 | G2192: =VLOOKUP(C2192,clientes!$C$3:$D$60,2,FALSE) -> JBS
A2193: 2026 | B2193: Dezembro | C2193: JBS | D2193: SODA CÁUSTICA | E2193: =VLOOKUP(D2193,'Lista de Produtos CLASSIFICAÇÃO'!$A$103:$B$144,2,FALSE) -> Soda Caustica | F2193: 226921 | G2193: =VLOOKUP(C2193,clientes!$C$3:$D$60,2,FALSE) -> JBS
...

Sheet clientes
C2: Cliente | D2: Grupo de Cliente
C3: AAK | D3: AAK DO BRASIL
C4: Acostagem | D4: ACOSTAGEM
C5: Adisseo | D5: ADISSEO
C6: Adisseo Caminhão | D6: ADISSEO
C7: ADM | D7: ADM
C8: Agropalma | D8: AGROPALMA
C9: Ares | D9: ARES MERCHANTS PTE LIMITE
C10: Art Petro | D10: ART PETRO
C11: Atem | D11: ATEM
C12: BR | D12: BR
C13: Braskem | D13: BRASKEM
... C60: YPF | D60: YPF SOCIEDAD ANONIMA

Sheet Mov - Orçada
A1: ANO | B1: MÊS | C1: Cliente | D1: PRODUTO | E1: GRUPO DE PRODUTOS | F1: Movimentação(TON) | G1: Grupo de Cliente
A2: 2021 | B2: Janeiro | C2: Adisseo | D2: ALIMET | E2: =VLOOKUP(D2,'[2]Lista de Produtos CLASSIFICAÇÃO'!$E$103:$F$114,2,FALSE) -> Outros | F2: 3000 | G2: =VLOOKUP(Tabela1[[#This Row],[Cliente]],clientes!$C$3:$D$60,2,FALSE) -> ADISSEO
A3: 2021 | B3: Janeiro | C3: Adisseo | D3: ALIMET | E3: =VLOOKUP(D3,'[2]Lista de Produtos CLASSIFICAÇÃO'!$E$103:$F$114,2,FALSE) -> Outros | G3: =VLOOKUP(Tabela1[[#This Row],[Cliente]],clientes!$C$3:$D$60,2,FALSE) -> ADISSEO
A4: 2021 | B4: Janeiro | C4: Adisseo Caminhão | D4: ALIMET | E4: =VLOOKUP(D4,'[2]Lista de Produtos CLASSIFICAÇÃO'!$E$103:$F$114,2,FALSE) -> Outros | F4: 150 | G4: =VLOOKUP(Tabela1[[#This Row],[Cliente]],clientes!$C$3:$D$60,2,FALSE) -> ADISSEO
A5: 2021 | B5: Janeiro | C5: ADM | D5: GLICERINA | E5: =VLOOKUP(D5,'[2]Lista de Produtos CLASSIFICAÇÃO'!$E$103:$F$114,2,FALSE) -> #N/A | F5: 350 | G5: =VLOOKUP(Tabela1[[#This Row],[Cliente]],clientes!$C$3:$D$60,2,FALSE) -> ADM
A6: 2021 | B6: Janeiro | C6: Ipiranga | D6: DIESEL/GASOLINA | E6: =VLOOKUP(D6,'[2]Lista de Produtos CLASSIFICAÇÃO'!$E$103:$F$114,2,FALSE) -> Derivados | F6: 113295 | G6: =VLOOKUP(Tabela1[[#This Row],[Cliente]],clientes!$C$3:$D$60,2,FALSE) -> IPIRANGA
A7: 2021 | B7: Janeiro | C7: BR | D7: DIESEL/GASOLINA | E7: =VLOOKUP(D7,'[2]Lista de Produtos CLASSIFICAÇÃO'!$E$103:$F$114,2,FALSE) -> Derivados | F7: 62582 | G7: =VLOOKUP(Tabela1[[#This Row],[Cliente]],clientes!$C$3:$D$60,2,FALSE) -> BR
A8: 2021 | B8: Janeiro | C8: Greenergy | D8: DIESEL/GASOLINA | E8: =VLOOKUP(D8,'[2]Lista de Produtos CLASSIFICAÇÃO'!$E$103:$F$114,2,FALSE) -> Derivados | F8: 18691 | G8: =VLOOKUP(Tabela1[[#This Row],[Cliente]],clientes!$C$3:$D$60,2,FALSE) -> GREENENERGY
A9: 2021 | B9: Janeiro | C9: Sul Plata | D9: DIESEL/GASOLINA | E9: =VLOOKUP(D9,'[2]Lista de Produtos CLASSIFICAÇÃO'!$E$103:$F$114,2,FALSE) -> Derivados | F9: 40338 | G9: =VLOOKUP(Tabela1[[#This Row],[Cliente]],clientes!$C$3:$D$60,2,FALSE) -> SUL PLATA
A10: 2021 | B10: Janeiro | C10: Sul Plata | D10: DIESEL/GASOLINA | E10: =VLOOKUP(D10,'[2]Lista de Produtos CLASSIFICAÇÃO'!$E$103:$F$114,2,FALSE) -> Derivados | G10: =VLOOKUP(Tabela1[[#This Row],[Cliente]],clientes!$C$3:$D$60,2,FALSE) -> SUL PLATA
A11: 2021 | B11: Janeiro | C11: JBS | D11: SODA CÁUSTICA | E11: =VLOOKUP(D11,'[2]Lista de Produtos CLASSIFICAÇÃO'!$E$103:$F$114,2,FALSE) -> Soda Caustica | F11: 2300 | G11: =VLOOKUP(Tabela1[[#This Row],[Cliente]],clientes!$C$3:$D$60,2,FALSE) -> JBS
A12: 2021 | B12: Janeiro | C12: Tricon | D12: SODA CÁUSTICA | E12: =VLOOKUP(D12,'[2]Lista de Produtos CLASSIFICAÇÃO'!$E$103:$F$114,2,FALSE) -> Soda Caustica | F12: 3200 | G12: =VLOOKUP(Tabela1[[#This Row],[Cliente]],clientes!$C$3:$D$60,2,FALSE) -> TRICON ENERGY
A13: 2021 | B13: Janeiro | C13: Novus | D13: ALIMET | E13: =VLOOKUP(D13,'[2]Lista de Produtos CLASSIFICAÇÃO'!$E$103:$F$114,2,FALSE) -> Outros | F13: 2000 | G13: =VLOOKUP(Tabela1[[#This Row],[Cliente]],clientes!$C$3:$D$60,2,FALSE) -> NOVUS
A14: 2021 | B14: Janeiro | C14: BRF | D14: AQUECIDOS | E14: =VLOOKUP(D14,'[2]Lista de Produtos CLASSIFICAÇÃO'!$E$103:$F$114,2,FALSE) -> Aquecidos | F14: 3000 | G14: =VLOOKUP(Tabela1[[#This Row],[Cliente]],clientes!$C$3:$D$60,2,FALSE) -> BRF
A15: 2021 | B15: Janeiro | C15: JBS | D15: AQUECIDOS | E15: =VLOOKUP(D15,'[2]Lista de Produtos CLASSIFICAÇÃO'!$E$103:$F$114,2,FALSE) -> Aquecidos | F15: 1300 | G15: =VLOOKUP(Tabela1[[#This Row],[Cliente]],clientes!$C$3:$D$60,2,FALSE) -> JBS
A16: 2021 | B16: Janeiro | C16: Cargill | D16: AQUECIDOS | E16: =VLOOKUP(D16,'[2]Lista de Produtos CLASSIFICAÇÃO'!$E$103:$F$114,2,FALSE) -> Aquecidos | F16: 3500 | G16: =VLOOKUP(Tabela1[[#This Row],[Cliente]],clientes!$C$3:$D$60,2,FALSE) -> CARGILL
A17: 2021 | B17: Janeiro | C17: Pool | D17: ÓLEO VEGETAL | E17: =VLOOKUP(D17,'[2]Lista de Produtos CLASSIFICAÇÃO'!$E$103:$F$114,2,FALSE) -> Óleo Vegetal | F17: 11500 | G17: =VLOOKUP(Tabela1[[#This Row],[Cliente]],clientes!$C$3:$D$60,2,FALSE) -> POOL
A18: 2021 | B18: Janeiro | C18: Pool Excedente | D18: ÓLEO VEGETAL | E18: =VLOOKUP(D18,'[2]Lista de Produtos CLASSIFICAÇÃO'!$E$103:$F$114,2,FALSE) -> Óleo Vegetal | G18: =VLOOKUP(Tabela1[[#This Row],[Cliente]],clientes!$C$3:$D$60,2,FALSE) -> POOL EXCEDENTE
A19: 2021 | B19: Janeiro | C19: Methanex | D19: METANOL | E19: =VLOOKUP(D19,'[2]Lista de Produtos CLASSIFICAÇÃO'!$E$103:$F$114,2,FALSE) -> Metanol | F19: 52000 | G19: =VLOOKUP(Tabela1[[#This Row],[Cliente]],clientes!$C$3:$D$60,2,FALSE) -> METHANEX
A20: 2021 | B20: Janeiro | C20: Mitsubishi | D20: METANOL | E20: =VLOOKUP(D20,'[2]Lista de Produtos CLASSIFICAÇÃO'!$E$103:$F$114,2,FALSE) -> Metanol | F20: 13000 | G20: =VLOOKUP(Tabela1[[#This Row],[Cliente]],clientes!$C$3:$D$60,2,FALSE) -> MITSUBISHI
A21: 2021 | B21: Janeiro | C21: SCC | D21: METANOL | E21: =VLOOKUP(D21,'[2]Lista de Produtos CLASSIFICAÇÃO'!$E$103:$F$114,2,FALSE) -> Metanol | F21: 20000 | G21: =VLOOKUP(Tabela1[[#This Row],[Cliente]],clientes!$C$3:$D$60,2,FALSE) -> SCC
A22: 2021 | B22: Janeiro | C22: SCC | D22: METANOL | E22: =VLOOKUP(D22,'[2]Lista de Produtos CLASSIFICAÇÃO'!$E$103:$F$114,2,FALSE) -> Metanol | G22: =VLOOKUP(Tabela1[[#This Row],[Cliente]],clientes!$C$3:$D$60,2,FALSE) -> SCC
A23: 2021 | B23: Janeiro | C23: Hinove | D23: FERTILIZANTE | E23: =VLOOKUP(D23,'[2]Lista de Produtos CLASSIFICAÇÃO'!$E$103:$F$114,2,FALSE) -> #N/A | G23: =VLOOKUP(Tabela1[[#This Row],[Cliente]],clientes!$C$3:$D$60,2,FALSE) -> HINOVE
A24: 2021 | B24: Janeiro | C24: Evonik | D24: METILATO | E24: =VLOOKUP(D24,'[2]Lista de Produtos CLASSIFICAÇÃO'!$E$103:$F$114,2,FALSE) -> Outros | F24: 1200 | G24: =VLOOKUP(Tabela1[[#This Row],[Cliente]],clientes!$C$3:$D$60,2,FALSE) -> EVONIK
A25: 2021 | B25: Janeiro | C25: YPF | D25: METANOL | E25: =VLOOKUP(D25,'[2]Lista de Produtos CLASSIFICAÇÃO'!$E$103:$F$114,2,FALSE) -> Metanol | G25: =VLOOKUP(Tabela1[[#This Row],[Cliente]],clientes!$C$3:$D$60,2,FALSE) -> YPF SOCIEDAD ANONIMA
A26: 2021 | B26: Janeiro | C26: GTM | D26: METILATO | E26: =VLOOKUP(D26,'[2]Lista de Produtos CLASSIFICAÇÃO'!$E$103:$F$114,2,FALSE) -> Outros | G26: =VLOOKUP(Tabela1[[#This Row],[Cliente]],clientes!$C$3:$D$60,2,FALSE) -> GTM
A27: 2021 | B27: Janeiro | C27: DRT | D27: TEREBINTINA | E27: =VLOOKUP(D27,'[2]Lista de Produtos CLASSIFICAÇÃO'!$E$103:$F$114,2,FALSE) -> #N/A | F27: 400 | G27: =VLOOKUP(Tabela1[[#This Row],[Cliente]],clientes!$C$3:$D$60,2,FALSE) -> DRT
A28: 2021 | B28: Janeiro | C28: Tereos/Inpasa/Glencore | D28: ÁLCOOL | E28: =VLOOKUP(D28,'[2]Lista de Produtos CLASSIFICAÇÃO'!$E$103:$F$114,2,FALSE) -> Biocombustíveis | G28: =VLOOKUP(Tabela1[[#This Row],[Cliente]],clientes!$C$3:$D$60,2,FALSE) -> TEREOS / INPASA / GLENCORE
A29: 2021 | B29: Janeiro | C29: Celena | D29: AQUECIDOS | E29: =VLOOKUP(D29,'[2]Lista de Produtos CLASSIFICAÇÃO'!$E$103:$F$114,2,FALSE) -> Aquecidos | F29: 3000 | G29: =VLOOKUP(Tabela1[[#This Row],[Cliente]],clientes!$C$3:$D$60,2,FALSE) -> CELENA
A30: 2021 | B30: Janeiro | C30: AAK | D30: AQUECIDOS | E30: =VLOOKUP(D30,'[2]Lista de Produtos CLASSIFICAÇÃO'!$E$103:$F$114,2,FALSE) -> Aquecidos | F30: 2000 | G30: =VLOOKUP(Tabela1[[#This Row],[Cliente]],clientes!$C$3:$D$60,2,FALSE) -> AAK DO BRASIL
A31: 2021 | B31: Janeiro | C31: Cargill | D31: ÓLEO VEGETAL | E31: =VLOOKUP(D31,'[2]Lista de Produtos CLASSIFICAÇÃO'!$E$103:$F$114,2,FALSE) -> Óleo Vegetal | F31: 5000 | G31: =VLOOKUP(Tabela1[[#This Row],[Cliente]],clientes!$C$3:$D$60,2,FALSE) -> CARGILL
A32: 2021 | B32: Janeiro | C32: Agropalma | D32: AQUECIDOS | E32: =VLOOKUP(D32,'[2]Lista de Produtos CLASSIFICAÇÃO'!$E$103:$F$114,2,FALSE) -> Aquecidos | F32: 3000 | G32: =VLOOKUP(Tabela1[[#This Row],[Cliente]],clientes!$C$3:$D$60,2,FALSE) -> AGROPALMA
A33: 2021 | B33: Janeiro | C33: Copape | D33: NAFTA | E33: =VLOOKUP(D33,'[2]Lista de Produtos CLASSIFICAÇÃO'!$E$103:$F$114,2,FALSE) -> #N/A | F33: 17500 | G33: =VLOOKUP(Tabela1[[#This Row],[Cliente]],clientes!$C$3:$D$60,2,FALSE) -> COPAPE
A34: 2021 | B34: Fevereiro | C34: Adisseo | D34: ALIMET | E34: =VLOOKUP(D34,'[2]Lista de Produtos CLASSIFICAÇÃO'!$E$103:$F$114,2,FALSE) -> Outros | F34: 3000 | G34: =VLOOKUP(Tabela1[[#This Row],[Cliente]],clientes!$C$3:$D$60,2,FALSE) -> ADISSEO
A35: 2021 | B35: Fevereiro | C35: Adisseo | D35: ALIMET | E35: =VLOOKUP(D35,'[2]Lista de Produtos CLASSIFICAÇÃO'!$E$103:$F$114,2,FALSE) -> Outros | G35: =VLOOKUP(Tabela1[[#This Row],[Cliente]],clientes!$C$3:$D$60,2,FALSE) -> ADISSEO
A36: 2021 | B36: Fevereiro | C36: Adisseo Caminhão | D36: ALIMET | E36: =VLOOKUP(D36,'[2]Lista de Produtos CLASSIFICAÇÃO'!$E$103:$F$114,2,FALSE) -> Outros | F36: 150 | G36: =VLOOKUP(Tabela1[[#This Row],[Cliente]],clientes!$C$3:$D$60,2,FALSE) -> ADISSEO
A37: 2021 | B37: Fevereiro | C37: ADM | D37: GLICERINA | E37: =VLOOKUP(D37,'[2]Lista de Produtos CLASSIFICAÇÃO'!$E$103:$F$114,2,FALSE) -> #N/A | F37: 350 | G37: =VLOOKUP(Tabela1[[#This Row],[Cliente]],clientes!$C$3:$D$60,2,FALSE) -> ADM
A38: 2021 | B38: Fevereiro | C38: Ipiranga | D38: DIESEL/GASOLINA | E38: =VLOOKUP(D38,'[2]Lista de Produtos CLASSIFICAÇÃO'!$E$103:$F$114,2,FALSE) -> Derivados | F38: 113295 | G38: =VLOOKUP(Tabela1[[#This Row],[Cliente]],clientes!$C$3:$D$60,2,FALSE) -> IPIRANGA
A39: 2021 | B39: Fevereiro | C39: BR | D39: DIESEL/GASOLINA | E39: =VLOOKUP(D39,'[2]Lista de Produtos CLASSIFICAÇÃO'!$E$103:$F$114,2,FALSE) -> Derivados | F39: 53950 | G39: =VLOOKUP(Tabela1[[#This Row],[Cliente]],clientes!$C$3:$D$60,2,FALSE) -> BR
A40: 2021 | B40: Fevereiro | C40: Greenergy | D40: DIESEL/GASOLINA | E40: =VLOOKUP(D40,'[2]Lista de Produtos CLASSIFICAÇÃO'!$E$103:$F$114,2,FALSE) -> Derivados | F40: 18691 | G40: =VLOOKUP(Tabela1[[#This Row],[Cliente]],clientes!$C$3:$D$60,2,FALSE) -> GREENENERGY
...

Sheet Projeção - Ton  Movimentação
A1: ID | B1: # | C1: CT | D1: Cliente | E1: Produto | F1: Column19 | G1: Ano | H1: Atributo | I1: Valor
A2: TRUE | B2: 2 | C2: CT-1 | D2: Adisseo | E2: ALIMET | G2: 2023 | H2: janeiro | I2: 3600
A3: TRUE | B3: 2 | C3: CT-1 | D3: Adisseo | E3: ALIMET | G3: 2023 | H3: fevereiro | I3: 3600
A4: TRUE | B4: 2 | C4: CT-1 | D4: Adisseo | E4: ALIMET | G4: 2023 | H4: março | I4: 3600
A5: TRUE | B5: 2 | C5: CT-1 | D5: Adisseo | E5: ALIMET | G5: 2023 | H5: abril | I5: 3600
A6: TRUE | B6: 2 | C6: CT-1 | D6: Adisseo | E6: ALIMET | G6: 2023 | H6: maio | I6: 3600
A7: TRUE | B7: 2 | C7: CT-1 | D7: Adisseo | E7: ALIMET | G7: 2023 | H7: junho | I7: 3600
A8: TRUE | B8: 2 | C8: CT-1 | D8: Adisseo | E8: ALIMET | G8: 2023 | H8: julho | I8: 3600
A9: TRUE | B9: 2 | C9: CT-1 | D9: Adisseo | E9: ALIMET | G9: 2023 | H9: agosto | I9: 3600
A10: TRUE | B10: 2 | C10: CT-1 | D10: Adisseo | E10: ALIMET | G10: 2023 | H10: setembro | I10: 3600
A11: TRUE | B11: 2 | C11: CT-1 | D11: Adisseo | E11: ALIMET | G11: 2023 | H11: outubro | I11: 3600
A12: TRUE | B12: 2 | C12: CT-1 | D12: Adisseo | E12: ALIMET | G12: 2023 | H12: novembro | I12: 3600
A13: TRUE | B13: 2 | C13: CT-1 | D13: Adisseo | E13: ALIMET | G13: 2023 | H13: dezembro | I13: 3600
... A338: TRUE | B338: 34 | C338: CT-3 | D338: Atem | E338: DIESEL/GASOLINA | G338: 2023 | H338: dezembro | I338: 8300

Sheet Orçado
A1: DadosExternos_1

Sheet TD - Produto
A1: MÊS | B1: (Tudo)
A3: Soma de Faturamento (R$) | B3: Rótulos de Coluna
A4: Rótulos de Linha | B4: 2021 | C4: 2022 | D4: 2023 | E4: 2024 | F4: 2025 | G4: Total Geral
A5: GLICERINA | B5: 932826 | G5: 932826
A6: DIETILENO GLICOL | D6: 2367244 | E6: 2307960 | G6: 4675204
A7: METANOL | B7: 161536389 | C7: 189582999 | D7: 175219572 | E7: 181064314 | F7: 234619440 | G7: 942022714
A8: BIODIESEL | D8: 3900600 | E8: 5613492 | F8: 5255628 | G8: 14769720
A9: NAFTA | B9: 17313708 | C9: 1678929 | G9: 18992637
A10: SODA CÁUSTICA | B10: 5237520 | C10: 26015351 | D10: 34832289 | E10: 33562581 | F10: 37155935 | G10: 136803676
A11: ALIMET | B11: 9801578 | C11: 8638296 | D11: 9175260 | E11: 10641720 | F11: 10541808 | G11: 48798662
A12: AQUECIDOS | B12: 27354182 | C12: 41955534 | D12: 46381911 | E12: 77518067 | F12: 86416555 | G12: 279626249
A13: ÓLEO VEGETAL | B13: 35232206 | C13: 61970966 | D13: 78090809 | E13: 75666050 | F13: 40390387 | G13: 291350418
A14: DIESEL/GASOLINA | B14: 177760406 | C14: 137369238 | D14: 180700776 | E14: 204583323 | F14: 206312808 | G14: 906726551
A15: METILATO | B15: 3668526 | C15: 4321383 | D15: 3567672 | E15: 4877400 | F15: 5279292 | G15: 21714273
A16: XILENO | E16: 1763992 | G16: 1763992
A17: ÁLCOOL | B17: 2100000 | C17: 3500000 | D17: 4500000 | E17: 10200000 | F17: 28741848 | G17: 49041848
A18: ACOSTAGEM | E18: 5489461.5 | F18: 5881124.5 | G18: 11370586
A19: Total Geral | B19: 440937341 | C19: 475032696 | D19: 538736133 | E19: 6.1328836e+08 | F19: 6.6059483e+08 | G19: 2.7285894e+09

Sheet TD - Grupo
A1: MÊS | B1: (Tudo)
A3: Soma de Faturamento (R$) | B3: Rótulos de Coluna
A4: Rótulos de Linha | B4: 2021 | C4: 2022 | D4: 2023 | E4: 2024 | F4: 2025 | G4: Total Geral
A5: Aquecidos | B5: 27354182 | C5: 41955534 | D5: 46381911 | E5: 77518067 | F5: 86416555 | G5: 279626249
A6: Biocombustíveis | B6: 2100000 | C6: 3500000 | D6: 8400600 | E6: 15813492 | F6: 33997476 | G6: 63811568
A7: Derivados | B7: 177760406 | C7: 137369238 | D7: 180700776 | E7: 204583323 | F7: 206312808 | G7: 906726551
A8: Metanol | B8: 161536389 | C8: 189582999 | D8: 175219572 | E8: 181064314 | F8: 234619440 | G8: 942022714
A9: Óleo Vegetal | B9: 35232206 | C9: 61970966 | D9: 78090809 | E9: 75666050 | F9: 40390387 | G9: 291350418
A10: Outros | B10: 13470104 | C10: 12959679 | D10: 15110176 | E10: 19591072 | F10: 15821100 | G10: 76952131
A11: Soda Caustica | B11: 5237520 | C11: 26015351 | D11: 34832289 | E11: 33562581 | F11: 37155935 | G11: 136803676
A12: Acostagem | E12: 5489461.5 | F12: 5881124.5 | G12: 11370586
A13: Total Geral | B13: 422690807 | C13: 473353767 | D13: 538736133 | E13: 6.1328836e+08 | F13: 6.6059483e+08 | G13: 2.7086639e+09

Sheet Projeção-Ocupação
A1: Ano | B1: Mês | C1: CT | D1: Cliente | E1: Grupo Cliente | F1: Produto | G1: GRUPO DE PRODUTO | H1: Vol_m3
A2: 2021 | B2: janeiro | C2: CT-2 | D2: AAK | E2: =VLOOKUP(D2,clientes!$C$3:$D$60,2,FALSE) -> AAK DO BRASIL | F2: AQUECIDOS | G2: =VLOOKUP(F2,'[2]Lista de Produtos CLASSIFICAÇÃO'!$E$103:$F$114,2,FALSE) -> Aquecidos | H2: 5555
A3: 2021 | B3: fevereiro | C3: CT-2 | D3: AAK | E3: =VLOOKUP(D3,clientes!$C$3:$D$60,2,FALSE) -> AAK DO BRASIL | F3: AQUECIDOS | G3: =VLOOKUP(F3,'[2]Lista de Produtos CLASSIFICAÇÃO'!$E$103:$F$114,2,FALSE) -> Aquecidos | H3: 5555
A4: 2021 | B4: março | C4: CT-2 | D4: AAK | E4: =VLOOKUP(D4,clientes!$C$3:$D$60,2,FALSE) -> AAK DO BRASIL | F4: AQUECIDOS | G4: =VLOOKUP(F4,'[2]Lista de Produtos CLASSIFICAÇÃO'!$E$103:$F$114,2,FALSE) -> Aquecidos | H4: 5555
A5: 2021 | B5: abril | C5: CT-2 | D5: AAK | E5: =VLOOKUP(D5,clientes!$C$3:$D$60,2,FALSE) -> AAK DO BRASIL | F5: AQUECIDOS | G5: =VLOOKUP(F5,'[2]Lista de Produtos CLASSIFICAÇÃO'!$E$103:$F$114,2,FALSE) -> Aquecidos | H5: 5555
A6: 2021 | B6: maio | C6: CT-2 | D6: AAK | E6: =VLOOKUP(D6,clientes!$C$3:$D$60,2,FALSE) -> AAK DO BRASIL | F6: AQUECIDOS | G6: =VLOOKUP(F6,'[2]Lista de Produtos CLASSIFICAÇÃO'!$E$103:$F$114,2,FALSE) -> Aquecidos | H6: 5555
A7: 2021 | B7: junho | C7: CT-2 | D7: AAK | E7: =VLOOKUP(D7,clientes!$C$3:$D$60,2,FALSE) -> AAK DO BRASIL | F7: AQUECIDOS | G7: =VLOOKUP(F7,'[2]Lista de Produtos CLASSIFICAÇÃO'!$E$103:$F$114,2,FALSE) -> Aquecidos | H7: 5555
A8: 2021 | B8: julho | C8: CT-2 | D8: AAK | E8: =VLOOKUP(D8,clientes!$C$3:$D$60,2,FALSE) -> AAK DO BRASIL | F8: AQUECIDOS | G8: =VLOOKUP(F8,'[2]Lista de Produtos CLASSIFICAÇÃO'!$E$103:$F$114,2,FALSE) -> Aquecidos | H8: 5555
A9: 2021 | B9: agosto | C9: CT-2 | D9: AAK | E9: =VLOOKUP(D9,clientes!$C$3:$D$60,2,FALSE) -> AAK DO BRASIL | F9: AQUECIDOS | G9: =VLOOKUP(F9,'[2]Lista de Produtos CLASSIFICAÇÃO'!$E$103:$F$114,2,FALSE) -> Aquecidos | H9: 5555
A10: 2021 | B10: setembro | C10: CT-2 | D10: AAK | E10: =VLOOKUP(D10,clientes!$C$3:$D$60,2,FALSE) -> AAK DO BRASIL | F10: AQUECIDOS | G10: =VLOOKUP(F10,'[2]Lista de Produtos CLASSIFICAÇÃO'!$E$103:$F$114,2,FALSE) -> Aquecidos | H10: 5555
A11: 2021 | B11: outubro | C11: CT-2 | D11: AAK | E11: =VLOOKUP(D11,clientes!$C$3:$D$60,2,FALSE) -> AAK DO BRASIL | F11: AQUECIDOS | G11: =VLOOKUP(F11,'[2]Lista de Produtos CLASSIFICAÇÃO'!$E$103:$F$114,2,FALSE) -> Aquecidos | H11: 5555
A12: 2021 | B12: novembro | C12: CT-2 | D12: AAK | E12: =VLOOKUP(D12,clientes!$C$3:$D$60,2,FALSE) -> AAK DO BRASIL | F12: AQUECIDOS | G12: =VLOOKUP(F12,'[2]Lista de Produtos CLASSIFICAÇÃO'!$E$103:$F$114,2,FALSE) -> Aquecidos | H12: 5555
A13: 2021 | B13: dezembro | C13: CT-2 | D13: AAK | E13: =VLOOKUP(D13,clientes!$C$3:$D$60,2,FALSE) -> AAK DO BRASIL | F13: AQUECIDOS | G13: =VLOOKUP(F13,'[2]Lista de Produtos CLASSIFICAÇÃO'!$E$103:$F$114,2,FALSE) -> Aquecidos | H13: 5555
... A1633: 2025 | B1633: dezembro | C1633: CT-1 | D1633: Acostagem | E1633: =VLOOKUP(D1633,clientes!$C$3:$D$60,2,FALSE) -> ACOSTAGEM | F1633: ACOSTAGEM | G1633: =VLOOKUP(F1633,'[2]Lista de Produtos CLASSIFICAÇÃO'!$E$103:$F$114,2,FALSE) -> Acostagem | H1633: 0
A1634: 2025 | B1634: janeiro | D1634: Adicione 0 Linha(s) | E1634: =VLOOKUP(D1634,clientes!$C$3:$D$60,2,FALSE) -> #N/A | F1634: TOTAL | G1634: =VLOOKUP(F1634,'[2]Lista de Produtos CLASSIFICAÇÃO'!$E$103:$F$114,2,FALSE) -> #N/A | H1634: 676919
A1635: 2025 | B1635: fevereiro | D1635: Adicione 0 Linha(s) | E1635: =VLOOKUP(D1635,clientes!$C$3:$D$60,2,FALSE) -> #N/A | F1635: TOTAL | G1635: =VLOOKUP(F1635,'[2]Lista de Produtos CLASSIFICAÇÃO'!$E$103:$F$114,2,FALSE) -> #N/A | H1635: 673633
A1636: 2025 | B1636: março | D1636: Adicione 0 Linha(s) | E1636: =VLOOKUP(D1636,clientes!$C$3:$D$60,2,FALSE) -> #N/A | F1636: TOTAL | G1636: =VLOOKUP(F1636,'[2]Lista de Produtos CLASSIFICAÇÃO'!$E$103:$F$114,2,FALSE) -> #N/A | H1636: 715654
A1637: 2025 | B1637: abril | D1637: Adicione 0 Linha(s) | E1637: =VLOOKUP(D1637,clientes!$C$3:$D$60,2,FALSE) -> #N/A | F1637: TOTAL | G1637: =VLOOKUP(F1637,'[2]Lista de Produtos CLASSIFICAÇÃO'!$E$103:$F$114,2,FALSE) -> #N/A | H1637: 691224
A1638: 2025 | B1638: maio | D1638: Adicione 0 Linha(s) | E1638: =VLOOKUP(D1638,clientes!$C$3:$D$60,2,FALSE) -> #N/A | F1638: TOTAL | G1638: =VLOOKUP(F1638,'[2]Lista de Produtos CLASSIFICAÇÃO'!$E$103:$F$114,2,FALSE) -> #N/A | H1638: 698729
A1639: 2025 | B1639: junho | D1639: Adicione 0 Linha(s) | E1639: =VLOOKUP(D1639,clientes!$C$3:$D$60,2,FALSE) -> #N/A | F1639: TOTAL | G1639: =VLOOKUP(F1639,'[2]Lista de Produtos CLASSIFICAÇÃO'!$E$103:$F$114,2,FALSE) -> #N/A | H1639: 703037
A1640: 2025 | B1640: julho | D1640: Adicione 0 Linha(s) | E1640: =VLOOKUP(D1640,clientes!$C$3:$D$60,2,FALSE) -> #N/A | F1640: TOTAL | G1640: =VLOOKUP(F1640,'[2]Lista de Produtos CLASSIFICAÇÃO'!$E$103:$F$114,2,FALSE) -> #N/A | H1640: 723980
A1641: 2025 | B1641: agosto | D1641: Adicione 0 Linha(s) | E1641: =VLOOKUP(D1641,clientes!$C$3:$D$60,2,FALSE) -> #N/A | F1641: TOTAL | G1641: =VLOOKUP(F1641,'[2]Lista de Produtos CLASSIFICAÇÃO'!$E$103:$F$114,2,FALSE) -> #N/A | H1641: 692084
A1642: 2025 | B1642: setembro | D1642: Adicione 0 Linha(s) | E1642: =VLOOKUP(D1642,clientes!$C$3:$D$60,2,FALSE) -> #N/A | F1642: TOTAL | G1642: =VLOOKUP(F1642,'[2]Lista de Produtos CLASSIFICAÇÃO'!$E$103:$F$114,2,FALSE) -> #N/A | H1642: 691270
A1643: 2025 | B1643: outubro | D1643: Adicione 0 Linha(s) | E1643: =VLOOKUP(D1643,clientes!$C$3:$D$60,2,FALSE) -> #N/A | F1643: TOTAL | G1643: =VLOOKUP(F1643,'[2]Lista de Produtos CLASSIFICAÇÃO'!$E$103:$F$114,2,FALSE) -> #N/A | H1643: 686837
A1644: 2025 | B1644: novembro | D1644: Adicione 0 Linha(s) | E1644: =VLOOKUP(D1644,clientes!$C$3:$D$60,2,FALSE) -> #N/A | F1644: TOTAL | G1644: =VLOOKUP(F1644,'[2]Lista de Produtos CLASSIFICAÇÃO'!$E$103:$F$114,2,FALSE) -> #N/A | H1644: 683647
A1645: 2025 | B1645: dezembro | D1645: Adicione 0 Linha(s) | E1645: =VLOOKUP(D1645,clientes!$C$3:$D$60,2,FALSE) -> #N/A | F1645: TOTAL | G1645: =VLOOKUP(F1645,'[2]Lista de Produtos CLASSIFICAÇÃO'!$E$103:$F$114,2,FALSE) -> #N/A | H1645: 672787
A1646: 2025 | B1646: janeiro | C1646: CT-1 | D1646: Adisseo | E1646: =VLOOKUP(D1646,clientes!$C$3:$D$60,2,FALSE) -> ADISSEO | F1646: ALIMET | G1646: =VLOOKUP(F1646,'[2]Lista de Produtos CLASSIFICAÇÃO'!$E$103:$F$114,2,FALSE) -> Outros | H1646: 8500
A1647: 2025 | B1647: fevereiro | C1647: CT-1 | D1647: Adisseo | E1647: =VLOOKUP(D1647,clientes!$C$3:$D$60,2,FALSE) -> ADISSEO | F1647: ALIMET | G1647: =VLOOKUP(F1647,'[2]Lista de Produtos CLASSIFICAÇÃO'!$E$103:$F$114,2,FALSE) -> Outros | H1647: 8500
A1648: 2025 | B1648: março | C1648: CT-1 | D1648: Adisseo | E1648: =VLOOKUP(D1648,clientes!$C$3:$D$60,2,FALSE) -> ADISSEO | F1648: ALIMET | G1648: =VLOOKUP(F1648,'[2]Lista de Produtos CLASSIFICAÇÃO'!$E$103:$F$114,2,FALSE) -> Outros | H1648: 8500
A1649: 2025 | B1649: abril | C1649: CT-1 | D1649: Adisseo | E1649: =VLOOKUP(D1649,clientes!$C$3:$D$60,2,FALSE) -> ADISSEO | F1649: ALIMET | G1649: =VLOOKUP(F1649,'[2]Lista de Produtos CLASSIFICAÇÃO'!$E$103:$F$114,2,FALSE) -> Outros | H1649: 8500
A1650: 2025 | B1650: maio | C1650: CT-1 | D1650: Adisseo | E1650: =VLOOKUP(D1650,clientes!$C$3:$D$60,2,FALSE) -> ADISSEO | F1650: ALIMET | G1650: =VLOOKUP(F1650,'[2]Lista de Produtos CLASSIFICAÇÃO'!$E$103:$F$114,2,FALSE) -> Outros | H1650: 8500
A1651: 2025 | B1651: junho | C1651: CT-1 | D1651: Adisseo | E1651: =VLOOKUP(D1651,clientes!$C$3:$D$60,2,FALSE) -> ADISSEO | F1651: ALIMET | G1651: =VLOOKUP(F1651,'[2]Lista de Produtos CLASSIFICAÇÃO'!$E$103:$F$114,2,FALSE) -> Outros | H1651: 8500
A1652: 2025 | B1652: julho | C1652: CT-1 | D1652: Adisseo | E1652: =VLOOKUP(D1652,clientes!$C$3:$D$60,2,FALSE) -> ADISSEO | F1652: ALIMET | G1652: =VLOOKUP(F1652,'[2]Lista de Produtos CLASSIFICAÇÃO'!$E$103:$F$114,2,FALSE) -> Outros | H1652: 8500
A1653: 2025 | B1653: agosto | C1653: CT-1 | D1653: Adisseo | E1653: =VLOOKUP(D1653,clientes!$C$3:$D$60,2,FALSE) -> ADISSEO | F1653: ALIMET | G1653: =VLOOKUP(F1653,'[2]Lista de Produtos CLASSIFICAÇÃO'!$E$103:$F$114,2,FALSE) -> Outros | H1653: 8500
A1654: 2025 | B1654: setembro | C1654: CT-1 | D1654: Adisseo | E1654: =VLOOKUP(D1654,clientes!$C$3:$D$60,2,FALSE) -> ADISSEO | F1654: ALIMET | G1654: =VLOOKUP(F1654,'[2]Lista de Produtos CLASSIFICAÇÃO'!$E$103:$F$114,2,FALSE) -> Outros | H1654: 8500
A1655: 2025 | B1655: outubro | C1655: CT-1 | D1655: Adisseo | E1655: =VLOOKUP(D1655,clientes!$C$3:$D$60,2,FALSE) -> ADISSEO | F1655: ALIMET | G1655: =VLOOKUP(F1655,'[2]Lista de Produtos CLASSIFICAÇÃO'!$E$103:$F$114,2,FALSE) -> Outros | H1655: 8500
A1656: 2025 | B1656: novembro | C1656: CT-1 | D1656: Adisseo | E1656: =VLOOKUP(D1656,clientes!$C$3:$D$60,2,FALSE) -> ADISSEO | F1656: ALIMET | G1656: =VLOOKUP(F1656,'[2]Lista de Produtos CLASSIFICAÇÃO'!$E$103:$F$114,2,FALSE) -> Outros | H1656: 8500
A1657: 2025 | B1657: dezembro | C1657: CT-1 | D1657: Adisseo | E1657: =VLOOKUP(D1657,clientes!$C$3:$D$60,2,FALSE) -> ADISSEO | F1657: ALIMET | G1657: =VLOOKUP(F1657,'[2]Lista de Produtos CLASSIFICAÇÃO'!$E$103:$F$114,2,FALSE) -> Outros | H1657: 8500
... A2391: 2026 | B2391: janeiro | C2391: CT-4C | D2391: Methanex | E2391: =VLOOKUP(D2391,clientes!$C$3:$D$60,2,FALSE) -> METHANEX | F2391: METANOL | G2391: =VLOOKUP(F2391,'[2]Lista de Produtos CLASSIFICAÇÃO'!$E$103:$F$114,2,FALSE) -> Metanol | H2391: 0
A2392: 2026 | B2392: fevereiro | C2392: CT-4 | D2392: Methanex | E2392: =VLOOKUP(D2392,clientes!$C$3:$D$60,2,FALSE) -> METHANEX | F2392: METANOL | G2392: =VLOOKUP(F2392,'[2]Lista de Produtos CLASSIFICAÇÃO'!$E$103:$F$114,2,FALSE) -> Metanol | H2392: 119500 | J2392: OCUPA | K2392: 478000 | M2392: =K2392/K2393 -> 1.4230694
...

Sheet Projeção - Vol. Movimentação
A1: ANO | B1: MÊS | C1: Cliente | D1: PRODUTO | E1: GRUPO DE PRODUTOS | F1: Grupo de Cliente | G1: Movimentação(m³)
A2: 2026 | B2: Janeiro | C2: AAK | D2: AQUECIDOS | E2: =VLOOKUP(D2,'[2]Lista de Produtos CLASSIFICAÇÃO'!$E$103:$F$114,2,FALSE) -> Aquecidos | F2: =VLOOKUP(C2,clientes!$C$3:$D$60,2,FALSE) -> AAK DO BRASIL | G2: 4372.2222
A3: 2026 | B3: Janeiro | C3: ADM | D3: ÓLEO VEGETAL | E3: =VLOOKUP(D3,'[2]Lista de Produtos CLASSIFICAÇÃO'!$E$103:$F$114,2,FALSE) -> Óleo Vegetal | F3: =VLOOKUP(C3,clientes!$C$3:$D$60,2,FALSE) -> ADM | G3: 2826.087
A4: 2026 | B4: Janeiro | C4: Acostagem | D4: ACOSTAGEM | E4: =VLOOKUP(D4,'[2]Lista de Produtos CLASSIFICAÇÃO'!$E$103:$F$114,2,FALSE) -> Acostagem | F4: =VLOOKUP(C4,clientes!$C$3:$D$60,2,FALSE) -> ACOSTAGEM | G4: 0
A5: 2026 | B5: Janeiro | C5: Adisseo | D5: ALIMET | E5: =VLOOKUP(D5,'[2]Lista de Produtos CLASSIFICAÇÃO'!$E$103:$F$114,2,FALSE) -> Outros | F5: =VLOOKUP(C5,clientes!$C$3:$D$60,2,FALSE) -> ADISSEO | G5: 3461.5385
A6: 2026 | B6: Janeiro | C6: Ares | D6: AQUECIDOS | E6: =VLOOKUP(D6,'[2]Lista de Produtos CLASSIFICAÇÃO'!$E$103:$F$114,2,FALSE) -> Aquecidos | F6: =VLOOKUP(C6,clientes!$C$3:$D$60,2,FALSE) -> ARES MERCHANTS PTE LIMITE | G6: 3476.6667
A7: 2026 | B7: Janeiro | C7: Art Petro | D7: DIESEL/GASOLINA | E7: =VLOOKUP(D7,'[2]Lista de Produtos CLASSIFICAÇÃO'!$E$103:$F$114,2,FALSE) -> Derivados | F7: =VLOOKUP(C7,clientes!$C$3:$D$60,2,FALSE) -> ART PETRO | G7: 0
A8: 2026 | B8: Janeiro | C8: BRF | D8: AQUECIDOS | E8: =VLOOKUP(D8,'[2]Lista de Produtos CLASSIFICAÇÃO'!$E$103:$F$114,2,FALSE) -> Aquecidos | F8: =VLOOKUP(C8,clientes!$C$3:$D$60,2,FALSE) -> BRF | G8: 3526.6667
A9: 2026 | B9: Janeiro | C9: BSBIOS | D9: BIODIESEL | E9: =VLOOKUP(D9,'[2]Lista de Produtos CLASSIFICAÇÃO'!$E$103:$F$114,2,FALSE) -> Biocombustíveis | F9: =VLOOKUP(C9,clientes!$C$3:$D$60,2,FALSE) -> BSBIOS | G9: 6356.9767
A10: 2026 | B10: Janeiro | C10: BSC | D10: SODA CÁUSTICA | E10: =VLOOKUP(D10,'[2]Lista de Produtos CLASSIFICAÇÃO'!$E$103:$F$114,2,FALSE) -> Soda Caustica | F10: =VLOOKUP(C10,clientes!$C$3:$D$60,2,FALSE) -> BSC QUIMICA | G10: 1786.6667
A11: 2026 | B11: Janeiro | C11: Brenntag | D11: SODA CÁUSTICA | E11: =VLOOKUP(D11,'[2]Lista de Produtos CLASSIFICAÇÃO'!$E$103:$F$114,2,FALSE) -> Soda Caustica | F11: =VLOOKUP(C11,clientes!$C$3:$D$60,2,FALSE) -> BRENNTAG | G11: 1020
A12: 2026 | B12: Janeiro | C12: Bunge | D12: AQUECIDOS | E12: =VLOOKUP(D12,'[2]Lista de Produtos CLASSIFICAÇÃO'!$E$103:$F$114,2,FALSE) -> Aquecidos | F12: =VLOOKUP(C12,clientes!$C$3:$D$60,2,FALSE) -> BUNGE | G12: 2111.1111
A13: 2026 | B13: Janeiro | C13: Cargill | D13: AQUECIDOS | E13: =VLOOKUP(D13,'[2]Lista de Produtos CLASSIFICAÇÃO'!$E$103:$F$114,2,FALSE) -> Aquecidos | F13: =VLOOKUP(C13,clientes!$C$3:$D$60,2,FALSE) -> CARGILL | G13: 1035.5556
... A125: 2026 | B125: Março | C125: Methanex | D125: METANOL | E125: =VLOOKUP(D125,'[2]Lista de Produtos CLASSIFICAÇÃO'!$E$103:$F$114,2,FALSE) -> Metanol | F125: =VLOOKUP(C125,clientes!$C$3:$D$60,2,FALSE) -> METHANEX | G125: 83973.418
A126: 2026 | B126: Março | C126: Methanex | D126: METANOL | E126: =VLOOKUP(D126,'[2]Lista de Produtos CLASSIFICAÇÃO'!$E$103:$F$114,2,FALSE) -> Metanol | F126: =VLOOKUP(C126,clientes!$C$3:$D$60,2,FALSE) -> METHANEX | G126: 0 | L126: 1139383.5
A127: 2026 | B127: Março | C127: Mitsubishi | D127: METANOL | E127: =VLOOKUP(D127,'[2]Lista de Produtos CLASSIFICAÇÃO'!$E$103:$F$114,2,FALSE) -> Metanol | F127: =VLOOKUP(C127,clientes!$C$3:$D$60,2,FALSE) -> MITSUBISHI | G127: 12239.241
A128: 2026 | B128: Março | C128: OQ | D128: METANOL | E128: =VLOOKUP(D128,'[2]Lista de Produtos CLASSIFICAÇÃO'!$E$103:$F$114,2,FALSE) -> Metanol | F128: =VLOOKUP(C128,clientes!$C$3:$D$60,2,FALSE) -> OQ TRADING | G128: 21518.987
A129: 2026 | B129: Março | C129: OQ | D129: METANOL | E129: =VLOOKUP(D129,'[2]Lista de Produtos CLASSIFICAÇÃO'!$E$103:$F$114,2,FALSE) -> Metanol | F129: =VLOOKUP(C129,clientes!$C$3:$D$60,2,FALSE) -> OQ TRADING | G129: 0
A130: 2026 | B130: Março | C130: Olin | D130: SODA CÁUSTICA | E130: =VLOOKUP(D130,'[2]Lista de Produtos CLASSIFICAÇÃO'!$E$103:$F$114,2,FALSE) -> Soda Caustica | F130: =VLOOKUP(C130,clientes!$C$3:$D$60,2,FALSE) -> OLIN BLUE CUBE | G130: 15088.667
A131: 2026 | B131: Março | C131: Pool | D131: ÓLEO VEGETAL | E131: =VLOOKUP(D131,'[2]Lista de Produtos CLASSIFICAÇÃO'!$E$103:$F$114,2,FALSE) -> Óleo Vegetal | F131: =VLOOKUP(C131,clientes!$C$3:$D$60,2,FALSE) -> POOL | G131: 126305.02
A132: 2026 | B132: Março | C132: Pool Excedente | D132: ÓLEO VEGETAL | E132: =VLOOKUP(D132,'[2]Lista de Produtos CLASSIFICAÇÃO'!$E$103:$F$114,2,FALSE) -> Óleo Vegetal | F132: =VLOOKUP(C132,clientes!$C$3:$D$60,2,FALSE) -> POOL EXCEDENTE | G132: 652.17391
A133: 2026 | B133: Março | C133: Prisma | D133: BIODIESEL | E133: =VLOOKUP(D133,'[2]Lista de Produtos CLASSIFICAÇÃO'!$E$103:$F$114,2,FALSE) -> Biocombustíveis | F133: =VLOOKUP(C133,clientes!$C$3:$D$60,2,FALSE) -> PRISMA | G133: 5137.2093
A134: 2026 | B134: Março | C134: Raizen | D134: DIESEL/GASOLINA | E134: =VLOOKUP(D134,'[2]Lista de Produtos CLASSIFICAÇÃO'!$E$103:$F$114,2,FALSE) -> Derivados | F134: =VLOOKUP(C134,clientes!$C$3:$D$60,2,FALSE) -> RAIZEN | G134: 45000
A135: 2026 | B135: Março | C135: Rodoil | D135: DIESEL/GASOLINA | E135: =VLOOKUP(D135,'[2]Lista de Produtos CLASSIFICAÇÃO'!$E$103:$F$114,2,FALSE) -> Derivados | F135: =VLOOKUP(C135,clientes!$C$3:$D$60,2,FALSE) -> RODOOIL DISTRIBUIDORA | G135: 0
A136: 2026 | B136: Março | C136: Royal Fic | D136: DIESEL/GASOLINA | E136: =VLOOKUP(D136,'[2]Lista de Produtos CLASSIFICAÇÃO'!$E$103:$F$114,2,FALSE) -> Derivados | F136: =VLOOKUP(C136,clientes!$C$3:$D$60,2,FALSE) -> ROYAL FIC | G136: 0
A137: 2026 | B137: Março | C137: Sul Plata | D137: DIESEL/GASOLINA | E137: =VLOOKUP(D137,'[2]Lista de Produtos CLASSIFICAÇÃO'!$E$103:$F$114,2,FALSE) -> Derivados | F137: =VLOOKUP(C137,clientes!$C$3:$D$60,2,FALSE) -> SUL PLATA | G137: 36000
A138: 2026 | B138: Março | C138: Taurus | D138: DIESEL/GASOLINA | E138: =VLOOKUP(D138,'[2]Lista de Produtos CLASSIFICAÇÃO'!$E$103:$F$114,2,FALSE) -> Derivados | F138: =VLOOKUP(C138,clientes!$C$3:$D$60,2,FALSE) -> TAURUS | G138: 0
... A565: 2026 | B565: Dezembro | C565: Vibra | D565: DIESEL/GASOLINA | E565: =VLOOKUP(D565,'[2]Lista de Produtos CLASSIFICAÇÃO'!$E$103:$F$114,2,FALSE) -> Derivados | F565: =VLOOKUP(C565,clientes!$C$3:$D$60,2,FALSE) -> VIBRA | G565: 18000

Sheet Planilha4
C3: PRODUTO | D3: EXERCÍCIO
D4: 2020 | E4: 2021 | F4: 2022 | G4: 2023 | H4: 2024 | I4: 2025
C5: ÓLEO DE SOJA | D5: 669685 | E5: 706097 | F5: 1083725 | G5: 1107020 | H5: 479838 | I5: 717541
C6: ÓLEO DE ALGODÃO | D6: 0 | E6: 0 | F6: 0 | G6: 2999 | H6: 0 | I6: 0
C7: ÓLEO DE GIRASSOL | D7: 0 | E7: 14006 | F7: 0 | G7: 0 | H7: 0 | I7: 0
C8: ÓLEO DE MILHO | D8: 2008 | E8: 6002 | F8: 14804 | G8: 19059 | H8: 33836 | I8: 58582
C9: ÓLEO DE CANOLA | D9: 0 | E9: 0 | F9: 1502 | G9: 0 | H9: 0 | I9: 0
C10: ÓLEO DE PALMA | D10: 13704 | E10: 93503 | F10: 75065 | G10: 89057 | H10: 130147 | I10: 112895
C11: OLEINA DE PALMA/PALMISTE | D11: 0 | E11: 1497 | F11: 4491 | G11: 497 | H11: 4979 | I11: 7492
C12: ÓLEO DE PALMISTE | D12: 26405 | E12: 49600 | F12: 62486 | G12: 88713 | H12: 80307 | I12: 80541
C13: ESTEARINA PALMA/PALMISTE | D13: 1919 | E13: 19289 | F13: 16726 | G13: 26179 | H13: 34177 | I13: 31994
C14: GLICERINA | D14: 11302 | E14: 1859 | F14: 5104 | G14: 0 | H14: 0 | I14: 0
C15: VEGETAIS | D15: 725024 | E15: 891855 | F15: 1263902 | G15: 1333524 | H15: 763285 | I15: 1009045
C16: DIETILENO GLICOL | D16: 0 | E16: 0 | F16: 2191 | G16: 2590 | H16: 1830 | I16: 0
... C39: % | D39: 0.147 | E39: 0.1469 | F39: 0.1655 | G39: 0.1939 | H39: 0.1717 | I39: 0.175
C40: ACUMULADO | D40: 19222613

Sheet Planilha5
C3: PRODUTO | D3: EXERCÍCIO
D4: 2020 | E4: 2021 | F4: 2022 | G4: 2023 | H4: 2024 | I4: 2025
C5: ÓLEO DE SOJA | D5: 692195 | E5: 784442 | F5: 1218106 | G5: 1201469 | H5: 520920 | I5: 764541
C6: ÓLEO DE ALGODÃO | D6: 0 | E6: 0 | F6: 0 | G6: 2999 | H6: 0 | I6: 0
C7: ÓLEO DE GIRASSOL | D7: 1994 | E7: 15996 | F7: 0 | G7: 0 | H7: 0 | I7: 0
C8: ÓLEO DE MILHO | D8: 2008 | E8: 6002 | F8: 14804 | G8: 23590 | H8: 37836 | I8: 70009
C9: ÓLEO DE CANOLA | D9: 0 | E9: 0 | F9: 1502 | G9: 0 | H9: 0 | I9: 0
C10: ÓLEO DE PALMA | D10: 13704 | E10: 97496 | F10: 92583 | G10: 94233 | H10: 137262 | I10: 115987
C11: OLEINA DE PALMA/PALMISTE | D11: 0 | E11: 1497 | F11: 4989 | G11: 497 | H11: 4979 | I11: 8988
C12: ÓLEO DE PALMISTE | D12: 26405 | E12: 51583 | F12: 78089 | G12: 100750 | H12: 84550 | I12: 86035
C13: ESTEARINA PALMA/PALMISTE | D13: 1919 | E13: 19289 | F13: 19491 | G13: 27483 | H13: 34824 | I13: 34068
C14: GLICERINA | D14: 12891 | E14: 1859 | F14: 5104 | G14: 0 | H14: 0 | I14: 0
C15: VEGETAIS | D15: 751118 | E15: 978166 | F15: 1434667 | G15: 1451021 | H15: 820371 | I15: 1079628
C16: DIETILENO GLICOL | D16: 0 | E16: 0 | F16: 3674 | G16: 2590 | H16: 1830 | I16: 0
... C39: % | D39: 0.1495 | E39: 0.1478 | F39: 0.1716 | G39: 0.1901 | H39: 0.1704 | I39: 0.1706
C40: ACUMULADO | D40: 21762307

Sheet Diferença
C3: PRODUTO | D3: EXERCÍCIO
D4: 2020 | E4: 2021 | F4: 2022 | G4: 2023 | H4: 2024 | I4: 2025
C5: ÓLEO DE SOJA | D5: 22510 | E5: 78345 | F5: 134381 | G5: 94449 | H5: 41082 | I5: 47000
C6: ÓLEO DE ALGODÃO | D6: 0 | E6: 0 | F6: 0 | G6: 0 | H6: 0 | I6: 0
C7: ÓLEO DE GIRASSOL | D7: 1994 | E7: 1990 | F7: 0 | G7: 0 | H7: 0 | I7: 0
C8: ÓLEO DE MILHO | D8: 0 | E8: 0 | F8: 0 | G8: 4531 | H8: 4000 | I8: 11427
C9: ÓLEO DE CANOLA | D9: 0 | E9: 0 | F9: 0 | G9: 0 | H9: 0 | I9: 0
C10: ÓLEO DE PALMA | D10: 0 | E10: 3993 | F10: 17518 | G10: 5176 | H10: 7115 | I10: 3092
C11: OLEINA DE PALMA/PALMISTE | D11: 0 | E11: 0 | F11: 498 | G11: 0 | H11: 0 | I11: 1496
C12: ÓLEO DE PALMISTE | D12: 0 | E12: 1983 | F12: 15603 | G12: 12037 | H12: 4243 | I12: 5494
C13: ESTEARINA PALMA/PALMISTE | D13: 0 | E13: 0 | F13: 2765 | G13: 1304 | H13: 647 | I13: 2074
C14: GLICERINA | D14: 1589 | E14: 0 | F14: 0 | G14: 0 | H14: 0 | I14: 0
C15: DIETILENO GLICOL | D15: 0 | E15: 0 | F15: 1483 | G15: 0 | H15: 0 | I15: 0
C16: SEBO BOVINO | D16: 4995 | E16: 0 | F16: 0 | G16: 10312 | H16: 4035 | I16: 0
... C32: SODA CÁUSTICA | D32: 7657 | E32: 13932 | F32: 32826 | G32: 9925 | H32: 36749 | I32: 27558
